Workbook

Sheet 组件
B1: 库存更新日期： | E1: 46177 | F1: 组件库存不足的需要询问周文娟备货情况，不要直接使用 | K1: 此列勿动
B2: 玻璃类型 | C2: 功率 | D2: 排产情况 | E2: 物料编号 | F2: 物料名称 | G2: 仓库名称 | H2: 可用库存 | I2: 备注 | K2: 物料编号
B3: 双玻 | C3: 730W | D3: 在排产 | E3: 6B001492 | F3: 销售组件_TSM-NEG21C.20_730W_18BB_银边框_33mm_竖装_倒斜角_高反_2384*1303mm_Q1 | G3: 天合富家-南宁仓 | H3: ==VLOOKUP(G3&K3,工作表1!A:H,8,0) -> 2427 | K3: 6B001492
G4: 天合富家-徐州仓 | H4: ==VLOOKUP(G4&K4,工作表1!A:H,8,0) -> #N/A | K4: 6B001492
G5: 天合富家-佛山仓 | H5: ==VLOOKUP(G5&K5,工作表1!A:H,8,0) -> #N/A | K5: 6B001492
G6: 天合富家-郑州仓 | H6: ==VLOOKUP(G6&K6,工作表1!A:H,8,0) -> 9353 | K6: 6B001492
G7: 天合富家-金华仓 | H7: ==VLOOKUP(G7&K7,工作表1!A:H,8,0) -> 973 | K7: 6B001492
G8: 天合富家-常州西北仓 | H8: ==VLOOKUP(G8&K8,工作表1!A:H,8,0) -> 7737 | K8: 6B001492
G9: 天合富家-湘潭仓 | H9: ==VLOOKUP(G9&K9,工作表1!A:H,8,0) -> 2578 | K9: 6B001492
G10: 天合富家-武汉仓 | H10: ==VLOOKUP(G10&K10,工作表1!A:H,8,0) -> 3149 | K10: 6B001492
G11: 天合富家-济南仓 | H11: ==VLOOKUP(G11&K11,工作表1!A:H,8,0) -> 2899 | K11: 6B001492
C12: 720W | D12: 停止排产 | E12: 6B001455 | F12: 销售组件_TSM-NEG21C.20_720W_18BB_银边框_33mm_竖装_倒斜角_高反_2384*1303mm_Q | G12: 天合富家-常州西北仓 | H12: ==VLOOKUP(G12&K12,工作表1!A:H,8,0) -> 0 | K12: 6B001455
C13: 715W | D13: 停止排产 | E13: 6B001440 | F13: 销售组件_TSM-NEG21C.20_715W_18BB_银边框_33mm_竖装_倒斜角_高反_2384*1303mm_Q | G13: 天合富家-南宁仓 | H13: ==VLOOKUP(G13&K13,工作表1!A:H,8,0) -> #N/A | K13: 6B001440
G14: 天合富家-徐州仓 | H14: ==VLOOKUP(G14&K14,工作表1!A:H,8,0) -> #N/A | K14: 6B001440
G15: 天合富家-佛山仓 | H15: ==VLOOKUP(G15&K15,工作表1!A:H,8,0) -> #N/A | K15: 6B001440
G16: 天合富家-郑州仓 | H16: ==VLOOKUP(G16&K16,工作表1!A:H,8,0) -> 0 | K16: 6B001440
G17: 天合富家-金华仓 | H17: ==VLOOKUP(G17&K17,工作表1!A:H,8,0) -> 0 | K17: 6B001440
G18: 天合富家-常州西北仓 | H18: ==VLOOKUP(G18&K18,工作表1!A:H,8,0) -> 0 | K18: 6B001440
G19: 天合富家-湘潭仓 | H19: ==VLOOKUP(G19&K19,工作表1!A:H,8,0) -> 0 | K19: 6B001440
G20: 天合富家-武汉仓 | H20: ==VLOOKUP(G20&K20,工作表1!A:H,8,0) -> 0 | K20: 6B001440
G21: 天合富家-济南仓 | H21: ==VLOOKUP(G21&K21,工作表1!A:H,8,0) -> #N/A | K21: 6B001440
E22: 6B001469 | F22: 销售组件_TSM-NEG21C.20_715W_18BB_银边框_横/竖装_线缆长度+350/-280_EPE/高透_安装孔间距1400_2384*1303*33_Q1（华电江苏专用） | G22: 天合富家-常州西北仓 | H22: ==VLOOKUP(G22&K22,工作表1!A:H,8,0) -> 11 | I22: 江苏华电项目专用 | K22: 6B001469
G23: 天合富家-徐州仓 | H23: ==VLOOKUP(G23&K23,工作表1!A:H,8,0) -> #N/A | K23: 6B001469
G24: 天合富家-金华仓 | H24: ==VLOOKUP(G24&K24,工作表1!A:H,8,0) -> #N/A | K24: 6B001469
E25: 6B001476 | F25: 销售组件_TSM-NEG21C.20_715W_18BB_银边框_横/竖装_线缆长度+350/-280_EPE/高透_安装孔间距1400_2384*1303*33_Q1（华电河南直采） | G25: 天合富家-郑州仓 | H25: ==VLOOKUP(G25&K25,工作表1!A:H,8,0) -> 0 | I25: 河南华电项目专用 | K25: 6B001476
G26: 天合富家-常州西北仓 | H26: ==VLOOKUP(G26&K26,工作表1!A:H,8,0) -> 0 | K26: 6B001476
C27: 710W | D27: 停止排产 | E27: 6B001432 | F27: 销售组件_TSM-NEG21C.20_710W_18BB_银边框_横/竖装_线缆长度+350/-280_EPE/高透_安装孔间距1400_2384*1303*33_Q1（华电河南直采） | G27: 天合富家-郑州仓 | H27: ==VLOOKUP(G27&K27,工作表1!A:H,8,0) -> 0 | I27: 河南华电项目专用 | K27: 6B001432
E28: 6B001439 | F28: 销售组件_TSM-NEG21C.20_710W_18BB_银边框_横/竖装_线缆长度+350/-280_EPE/高透_安装孔间距1400_2384*1303*33_Q1（华电江苏专用） | G28: 天合富家-常州西北仓 | H28: ==VLOOKUP(G28&K28,工作表1!A:H,8,0) -> 166 | I28: 江苏华电项目专用 | K28: 6B001439
G29: 天合富家-徐州仓 | H29: ==VLOOKUP(G29&K29,工作表1!A:H,8,0) -> #N/A | K29: 6B001439
E30: 6B001413 | F30: 销售组件_TSM-NEG21C.20_710W_18BB_银边框_33mm_竖装_倒斜角_高反_2384*1303mm_Q | G30: 天合富家-湘潭仓 | H30: ==VLOOKUP(G30&K30,工作表1!A:H,8,0) -> #N/A | K30: 6B001413
G31: 天合富家-常州西北仓 | H31: ==VLOOKUP(G31&K31,工作表1!A:H,8,0) -> 0 | K31: 6B001413
G32: 天合富家-徐州仓 | H32: ==VLOOKUP(G32&K32,工作表1!A:H,8,0) -> #N/A | K32: 6B001413
G33: 天合富家-济南仓 | H33: ==VLOOKUP(G33&K33,工作表1!A:H,8,0) -> #N/A | K33: 6B001413
G34: 天合富家-郑州仓 | H34: ==VLOOKUP(G34&K34,工作表1!A:H,8,0) -> #N/A | K34: 6B001413
G35: 天合富家-昆明仓 | H35: ==VLOOKUP(G35&K35,工作表1!A:H,8,0) -> #N/A | K35: 6B001413
G36: 天合富家-佛山仓 | H36: ==VLOOKUP(G36&K36,工作表1!A:H,8,0) -> #N/A | K36: 6B001413
G37: 天合富家-武汉仓 | H37: ==VLOOKUP(G37&K37,工作表1!A:H,8,0) -> 0 | K37: 6B001413
C38: 705W | D38: 停止排产 | E38: 6B001431 | F38: 销售组件_TSM-NEG21C.20_705W_18BB_银边框_横/竖装_线缆长度+350/-280_EPE/高透_安装孔间距1400_2384*1303*33_Q1（华电河南直采） | G38: 天合富家-郑州仓 | H38: ==VLOOKUP(G38&K38,工作表1!A:H,8,0) -> 120 | I38: 河南华电项目专用 | K38: 6B001431
E39: 6B001438 | F39: 销售组件_TSM-NEG21C.20_705W_18BB_银边框_横/竖装_线缆长度+350/-280_EPE/高透_安装孔间距1400_2384*1303*33_Q1（华电江苏专用） | G39: 天合富家-常州西北仓 | H39: ==VLOOKUP(G39&K39,工作表1!A:H,8,0) -> 89 | I39: 江苏华电项目专用 | K39: 6B001438
G40: 天合富家-徐州仓 | H40: ==VLOOKUP(G40&K40,工作表1!A:H,8,0) -> #N/A | K40: 6B001438
...

Sheet 逆变器
B1: 库存更新日期： | C1: 46177 | E1: 如果不是项目强制要求，尽量不要使用原厂机 | J1: 此列勿动
B2: 厂家 | C2: 功率 | D2: 物料编号 | E2: 物料名称 | F2: 仓库名称 | G2: 可用库存 | H2: 备注 | J2: 物料编号 | K2: 价格排序（数字越大则越贵）
B3: 爱士惟 | C3: 6KW三相 | D3: AB002001 | E3: 组串式逆变器ASW6K-LT-G2 Pro_6kW_2路(16A/16A)_三相_180-1100V_IP66_WiFi_自然冷却 | F3: 天合富家-常州西北仓 | G3: ==VLOOKUP(F3&J3,工作表1!A:H,8,0) -> 20 | H3: 未上架 | J3: AB002001 | K3: #N/A
C4: 8KW单相 | D4: AA002219 | E4: 组串式逆变器_TS-SN8KTLE-T2_8kW_2路_单相_80-600_220/230V_NB/T32004_IP65_GPRS_自然冷却_天合原装专用(20A/20A) | F4: 天合富家-金华仓 | G4: ==VLOOKUP(F4&J4,工作表1!A:H,8,0) -> #N/A | J4: AA002219 | K4: 102
F5: 天合富家-常州西北仓 | G5: ==VLOOKUP(F5&J5,工作表1!A:H,8,0) -> #N/A | J5: AA002219 | K5: 102
F6: 天合富家-徐州仓 | G6: ==VLOOKUP(F6&J6,工作表1!A:H,8,0) -> #N/A | J6: AA002219 | K6: 102
C7: 10KW单相 | D7: AA002220 | E7: 组串式逆变器_TS-SN10KTLE-T3_10kW_3路_单相_80-600V_220/230V_NB/T32004_IP65_GPRS_自然冷却_天合原装专用(20A/16A/20A) | F7: 天合富家-武汉仓 | G7: ==VLOOKUP(F7&J7,工作表1!A:H,8,0) -> 0 | J7: AA002220 | K7: 130
F8: 天合富家-金华仓 | G8: ==VLOOKUP(F8&J8,工作表1!A:H,8,0) -> 0 | J8: AA002220 | K8: 130
F9: 天合富家-常州西北仓 | G9: ==VLOOKUP(F9&J9,工作表1!A:H,8,0) -> 10 | J9: AA002220 | K9: 130
F10: 天合富家-郑州仓 | G10: ==VLOOKUP(F10&J10,工作表1!A:H,8,0) -> #N/A | J10: AA002220 | K10: 130
C11: 10KW三相 | D11: AB002002 | E11: 组串式逆变器ASW10K-LT-G2 Pro_10kW_2路(20A/16A)_三相_180-1100V_IP66_WiFi_自然冷却 | F11: 天合富家-常州西北仓 | G11: ==VLOOKUP(F11&J11,工作表1!A:H,8,0) -> 160 | H11: 未上架 | J11: AB002002 | K11: #N/A
C12: 12KW三相 | D12: AA002151 | E12: 组串式逆变器_TS-SN12KTL3E-U2_12kW_2路_三相_125-1100V_380/400V_NB/T32004_IP65_GPRS_风冷_天合原装专用（32A/20A） | F12: 天合富家-佛山仓 | G12: ==VLOOKUP(F12&J12,工作表1!A:H,8,0) -> #N/A | J12: AA002151 | K12: 1
F13: 天合富家-南宁仓 | G13: ==VLOOKUP(F13&J13,工作表1!A:H,8,0) -> #N/A | J13: AA002151 | K13: 1
F14: 天合富家-武汉仓 | G14: ==VLOOKUP(F14&J14,工作表1!A:H,8,0) -> #N/A | J14: AA002151 | K14: 1
F15: 天合富家-金华仓 | G15: ==VLOOKUP(F15&J15,工作表1!A:H,8,0) -> 3 | J15: AA002151 | K15: 1
F16: 天合富家-常州西北仓 | G16: ==VLOOKUP(F16&J16,工作表1!A:H,8,0) -> 0 | J16: AA002151 | K16: 1
F17: 天合富家-济南仓 | G17: ==VLOOKUP(F17&J17,工作表1!A:H,8,0) -> 1 | J17: AA002151 | K17: 1
F18: 天合富家-徐州仓 | G18: ==VLOOKUP(F18&J18,工作表1!A:H,8,0) -> #N/A | J18: AA002151 | K18: 1
F19: 天合富家-郑州仓 | G19: ==VLOOKUP(F19&J19,工作表1!A:H,8,0) -> 0 | J19: AA002151 | K19: 1
D20: AB002013 | E20: 组串式逆变器ASW12K-LT-G2 Pro_12kW_2路(20A/20A)_三相_180-1100V_IP66_WiFi_自然冷却 | F20: 天合富家-常州西北仓 | G20: ==VLOOKUP(F20&J20,工作表1!A:H,8,0) -> 10 | H20: 未上架 | J20: AB002013 | K20: #N/A
C21: 17KW三相 | D21: AA002414 | E21: 组串式逆变器_TS-SN17KTL3E-U2_17kW_2路_三相_150-1100V_380/400V_NB/T32004_IP65_GPRS_风冷_天合原装专用（32A/32A） | F21: 天合富家-常州西北仓 | G21: ==VLOOKUP(F21&J21,工作表1!A:H,8,0) -> 0 | J21: AA002414 | K21: 67
F22: 天合富家-郑州仓 | G22: ==VLOOKUP(F22&J22,工作表1!A:H,8,0) -> 0 | J22: AA002414 | K22: 67
C23: 20KW三相 | D23: AA002415 | E23: 组串式逆变器_TS-SN20KTL3E-U2_20kW_2路_三相_150-1100V_380/400V_NB/T32004_IP65_GPRS_风冷_天合原装专用（32A/32A） | F23: 天合富家-武汉仓 | G23: ==VLOOKUP(F23&J23,工作表1!A:H,8,0) -> 0 | J23: AA002415 | K23: 57
F24: 天合富家-常州西北仓 | G24: ==VLOOKUP(F24&J24,工作表1!A:H,8,0) -> 38 | J24: AA002415 | K24: 57
C25: 25KW三相 | D25: AA002416 | E25: 组串式逆变器_TS-SN25KTL3E-U2_25kW_2路_三相_150-1100V_380/400V_NB/T32004_IP65_GPRS_风冷_天合原装专用（40A/32A） | F25: 天合富家-佛山仓 | G25: ==VLOOKUP(F25&J25,工作表1!A:H,8,0) -> #N/A | J25: AA002416 | K25: 87
F26: 天合富家-南宁仓 | G26: ==VLOOKUP(F26&J26,工作表1!A:H,8,0) -> #N/A | J26: AA002416 | K26: 87
F27: 天合富家-武汉仓 | G27: ==VLOOKUP(F27&J27,工作表1!A:H,8,0) -> #N/A | J27: AA002416 | K27: 87
F28: 天合富家-金华仓 | G28: ==VLOOKUP(F28&J28,工作表1!A:H,8,0) -> 0 | J28: AA002416 | K28: 87
F29: 天合富家-常州西北仓 | G29: ==VLOOKUP(F29&J29,工作表1!A:H,8,0) -> 18 | J29: AA002416 | K29: 87
F30: 天合富家-徐州仓 | G30: ==VLOOKUP(F30&J30,工作表1!A:H,8,0) -> #N/A | J30: AA002416 | K30: 87
F31: 天合富家-郑州仓 | G31: ==VLOOKUP(F31&J31,工作表1!A:H,8,0) -> 0 | J31: AA002416 | K31: 87
D32: AB001333 | E32: 组串式逆变器_ASW25K-LT-G2_25kW_2路_三相_180-1100V_380/400V_NB/T32004_IP66_4G/RS485_风冷_爱士惟(40A/32A) | F32: 天合富家-常州西北仓 | G32: ==VLOOKUP(F32&J32,工作表1!A:H,8,0) -> #N/A | H32: 原厂机 | J32: AB001333 | K32: 99
C33: 30KW三相 | D33: AB001066 | E33: 组串式逆变器_TS-SN30KTL3E-U3_30kW_3路_三相_200-1100V_380/400V_NB/T32004_IP65_GPRS_风冷_天合原装专用(40A/20A/30A) | F33: 天合富家-佛山仓 | G33: ==VLOOKUP(F33&J33,工作表1!A:H,8,0) -> #N/A | J33: AB001066 | K33: 119
F34: 天合富家-武汉仓 | G34: ==VLOOKUP(F34&J34,工作表1!A:H,8,0) -> #N/A | J34: AB001066 | K34: 119
F35: 天合富家-常州西北仓 | G35: ==VLOOKUP(F35&J35,工作表1!A:H,8,0) -> 0 | J35: AB001066 | K35: 119
F36: 天合富家-徐州仓 | G36: ==VLOOKUP(F36&J36,工作表1!A:H,8,0) -> #N/A | J36: AB001066 | K36: 119
D37: AB001334 | E37: 组串式逆变器_ASW30K-LT-G2_30kW_3路_三相_180-1100V_380/400V_NB/T32004_IP66_4G/RS485_风冷_爱士惟(40A/20A/40A) | F37: 天合富家-常州西北仓 | G37: ==VLOOKUP(F37&J37,工作表1!A:H,8,0) -> #N/A | H37: 原厂机 | J37: AB001334 | K37: 134
C38: 36KW三相 | D38: AB001176 | E38: 组串式逆变器_TS-SN36KTL3E-U4_36kW_4路_三相_180-1100V_380/400V_NB/T32004_IP65_GPRS_风冷_天合原装专用（40A/32A/20A/20A） | F38: 天合富家-武汉仓 | G38: ==VLOOKUP(F38&J38,工作表1!A:H,8,0) -> #N/A | J38: AB001176 | K38: 198
C39: 40KW三相 | D39: AB001177 | E39: 组串式逆变器_TS-SN40KTL3E-U4_40kW_4路_三相_180-1100V_380/400V_NB/T32004_IP65_GPRS_风冷_天合原装专用（40A/32A/20A/20A） | F39: 天合富家-武汉仓 | G39: ==VLOOKUP(F39&J39,工作表1!A:H,8,0) -> 0 | J39: AB001177 | K39: 201
F40: 天合富家-徐州仓 | G40: ==VLOOKUP(F40&J40,工作表1!A:H,8,0) -> #N/A | J40: AB001177 | K40: 201
...

Sheet 并网箱
B1: 库存更新日期： | C1: 46177 | J1: 此列勿动
B2: 并网箱类型 | C2: 功率 | D2: 物料编号 | E2: 物料名称 | F2: 仓库名称 | G2: 可用库存 | H2: 备注 | J2: 物料编号
B3: 标准一体式并网箱 | C3: 10KW单相 | D3: AA001062 | E3: 并网柜_10KW单相_220V_不锈钢_天合原装专用_TRP-DR-DQ-01-057 | F3: 天合富家-济南仓 | G3: ==VLOOKUP(F3&J3,工作表1!A:H,8,0) -> #N/A | J3: AA001062
F4: 天合富家-郑州仓 | G4: ==VLOOKUP(F4&J4,工作表1!A:H,8,0) -> #N/A | J4: AA001062
C5: 25KW三相 | D5: AA001061 | E5: 并网柜_25KW三相_380V_不锈钢_天合原装专用_TRP-DR-DQ-01-062 | F5: 天合富家-佛山仓 | G5: ==VLOOKUP(F5&J5,工作表1!A:H,8,0) -> #N/A | J5: AA001061
F6: 天合富家-南宁仓 | G6: ==VLOOKUP(F6&J6,工作表1!A:H,8,0) -> 30 | J6: AA001061
F7: 天合富家-武汉仓 | G7: ==VLOOKUP(F7&J7,工作表1!A:H,8,0) -> 84 | J7: AA001061
F8: 天合富家-金华仓 | G8: ==VLOOKUP(F8&J8,工作表1!A:H,8,0) -> 15 | J8: AA001061
F9: 天合富家-常州西北仓 | G9: ==VLOOKUP(F9&J9,工作表1!A:H,8,0) -> 14 | J9: AA001061
F10: 天合富家-济南仓 | G10: ==VLOOKUP(F10&J10,工作表1!A:H,8,0) -> 25 | J10: AA001061
F11: 天合富家-徐州仓 | G11: ==VLOOKUP(F11&J11,工作表1!A:H,8,0) -> #N/A | J11: AA001061
F12: 天合富家-湘潭仓 | G12: ==VLOOKUP(F12&J12,工作表1!A:H,8,0) -> 9 | J12: AA001061
F13: 天合富家-昆明仓 | G13: ==VLOOKUP(F13&J13,工作表1!A:H,8,0) -> 28 | J13: AA001061
F14: 天合富家-郑州仓 | G14: ==VLOOKUP(F14&J14,工作表1!A:H,8,0) -> 59 | J14: AA001061
C15: 30KW三相 | D15: AA001056 | E15: 并网柜_30KW三相_380V_不锈钢_天合原装专用_TRP-DR-DQ-01-063 | F15: 天合富家-佛山仓 | G15: ==VLOOKUP(F15&J15,工作表1!A:H,8,0) -> #N/A | J15: AA001056
F16: 天合富家-南宁仓 | G16: ==VLOOKUP(F16&J16,工作表1!A:H,8,0) -> 36 | J16: AA001056
F17: 天合富家-武汉仓 | G17: ==VLOOKUP(F17&J17,工作表1!A:H,8,0) -> 96 | J17: AA001056
F18: 天合富家-金华仓 | G18: ==VLOOKUP(F18&J18,工作表1!A:H,8,0) -> 28 | J18: AA001056
F19: 天合富家-常州西北仓 | G19: ==VLOOKUP(F19&J19,工作表1!A:H,8,0) -> 17 | J19: AA001056
F20: 天合富家-济南仓 | G20: ==VLOOKUP(F20&J20,工作表1!A:H,8,0) -> 19 | J20: AA001056
F21: 天合富家-徐州仓 | G21: ==VLOOKUP(F21&J21,工作表1!A:H,8,0) -> #N/A | J21: AA001056
F22: 天合富家-湘潭仓 | G22: ==VLOOKUP(F22&J22,工作表1!A:H,8,0) -> 9 | J22: AA001056
F23: 天合富家-昆明仓 | G23: ==VLOOKUP(F23&J23,工作表1!A:H,8,0) -> 77 | J23: AA001056
F24: 天合富家-郑州仓 | G24: ==VLOOKUP(F24&J24,工作表1!A:H,8,0) -> 12 | J24: AA001056
C25: 50KW三相 | D25: AA001653 | E25: 并网柜_50KW三相_380V_不锈钢_天合原装专用_TRP-DR-DQ-01-097 | F25: 天合富家-佛山仓 | G25: ==VLOOKUP(F25&J25,工作表1!A:H,8,0) -> #N/A | J25: AA001653
F26: 天合富家-南宁仓 | G26: ==VLOOKUP(F26&J26,工作表1!A:H,8,0) -> 91 | J26: AA001653
F27: 天合富家-武汉仓 | G27: ==VLOOKUP(F27&J27,工作表1!A:H,8,0) -> 112 | J27: AA001653
F28: 天合富家-金华仓 | G28: ==VLOOKUP(F28&J28,工作表1!A:H,8,0) -> 50 | J28: AA001653
F29: 天合富家-常州西北仓 | G29: ==VLOOKUP(F29&J29,工作表1!A:H,8,0) -> 19 | J29: AA001653
F30: 天合富家-济南仓 | G30: ==VLOOKUP(F30&J30,工作表1!A:H,8,0) -> 50 | J30: AA001653
F31: 天合富家-徐州仓 | G31: ==VLOOKUP(F31&J31,工作表1!A:H,8,0) -> #N/A | J31: AA001653
F32: 天合富家-昆明仓 | G32: ==VLOOKUP(F32&J32,工作表1!A:H,8,0) -> 207 | J32: AA001653
F33: 天合富家-郑州仓 | G33: ==VLOOKUP(F33&J33,工作表1!A:H,8,0) -> 10 | J33: AA001653
C34: 60KW三相 | D34: AA002624 | E34: 并网柜_60KW三相_380V_不锈钢_天合原装专用_TRP-DR-DQ-01-335 | F34: 天合富家-佛山仓 | G34: ==VLOOKUP(F34&J34,工作表1!A:H,8,0) -> #N/A | J34: AA002624
F35: 天合富家-武汉仓 | G35: ==VLOOKUP(F35&J35,工作表1!A:H,8,0) -> 11 | J35: AA002624
F36: 天合富家-金华仓 | G36: ==VLOOKUP(F36&J36,工作表1!A:H,8,0) -> 3 | J36: AA002624
F37: 天合富家-常州西北仓 | G37: ==VLOOKUP(F37&J37,工作表1!A:H,8,0) -> #N/A | J37: AA002624
F38: 天合富家-济南仓 | G38: ==VLOOKUP(F38&J38,工作表1!A:H,8,0) -> 9 | J38: AA002624
F39: 天合富家-湘潭仓 | G39: ==VLOOKUP(F39&J39,工作表1!A:H,8,0) -> 0 | J39: AA002624
F40: 天合富家-昆明仓 | G40: ==VLOOKUP(F40&J40,工作表1!A:H,8,0) -> 68 | J40: AA002624
...

Sheet 工作表1
B1: 仓库编号 | C1: 仓库名称 | D1: 物料编号 | E1: 物料名称 | F1: 物料类型 | G1: 单位 | H1: 可用库存
A2: ==C2&D2 -> 天合富家-武汉仓6B001364 | B2: TRP(HB)01 | C2: 天合富家-武汉仓 | D2: 6B001364 | E2: 销售组件_TDN-NEG04MC(II)_705W_18BB_银边框_横/竖装_倒斜角_EPE/高透_安装孔间距1400_2384*1303*33_Q1 | F2: 组件 | G2: PC | H2: 0
A3: ==C3&D3 -> 天合富家-武汉仓6B001396 | B3: TRP(HB)01 | C3: 天合富家-武汉仓 | D3: 6B001396 | E3: TDW-NEG04MC(II)_710W_18BB_银边框_横/竖装_倒斜角_EPE/高透_安装孔间距1400_2384*1303*33_Q1 | F3: 组件 | G3: PC | H3: 0
A4: ==C4&D4 -> 天合富家-售后仓6A002004 | B4: TRP(SH)01 | C4: 天合富家-售后仓 | D4: 6A002004 | E4: RSVG销售组件_TSM-PD14_320W_5BB_银边框_40mm_横装_Q1 | F4: 组件 | G4: PC | H4: 24
A5: ==C5&D5 -> 天合富家-售后仓6A003599 | B5: TRP(SH)01 | C5: 天合富家-售后仓 | D5: 6A003599 | E5: RSVG销售组件_TSM-PE15H_335W_5BB_银边框_35mm_竖装_Q1 | F5: 组件 | G5: PC | H5: 1
A6: ==C6&D6 -> 代理商虚拟仓6A008386 | B6: JXSXNC | C6: 代理商虚拟仓 | D6: 6A008386 | E6: RSVG销售组件_TSM-DE19_555W_12BB_银边框_35mm_竖装_倒斜角_高反_2384*1096mm_Q1 | F6: 组件 | G6: PC | H6: 44
A7: ==C7&D7 -> 代理商虚拟仓6B001055 | B7: JXSXNC | C7: 代理商虚拟仓 | D7: 6B001055 | E7: RSVG销售组件_TDW-DE04M(II)_660W_12BB_银边框_35mm_竖装_倒斜角_高反_2384*1303mm_Q1 | F7: 组件 | G7: PC | H7: 13
A8: ==C8&D8 -> 代理商虚拟仓6B001056 | B8: JXSXNC | C8: 代理商虚拟仓 | D8: 6B001056 | E8: RSVG销售组件_TDW-DE04M(II)_665W_12BB_银边框_35mm_竖装_倒斜角_高反_2384*1303mm_Q1 | F8: 组件 | G8: PC | H8: 24
A9: ==C9&D9 -> 代理商虚拟仓6B001083 | B9: JXSXNC | C9: 代理商虚拟仓 | D9: 6B001083 | E9: RSVG销售组件_TSM-DE21_660W_12BB_银边框_33mm_竖装_倒斜角_高反_2384*1303mm_Q1 | F9: 组件 | G9: PC | H9: 0
A10: ==C10&D10 -> 代理商虚拟仓6B001084 | B10: JXSXNC | C10: 代理商虚拟仓 | D10: 6B001084 | E10: RSVG销售组件_TSM-DE21_665W_12BB_银边框_33mm_竖装_倒斜角_高反_2384*1303mm_Q1 | F10: 组件 | G10: PC | H10: 0
A11: ==C11&D11 -> 代理商虚拟仓6B001160 | B11: JXSXNC | C11: 代理商虚拟仓 | D11: 6B001160 | E11: 销售组件_TDA-DEG04MC(II)_665W_12BB_银边框_横/竖装_倒斜角_高透/EPE_2384*1303*35_Q1 | F11: 组件 | G11: PC | H11: 0
A12: ==C12&D12 -> 代理商虚拟仓6B001252 | B12: JXSXNC | C12: 代理商虚拟仓 | D12: 6B001252 | E12: 销售组件_TDW-DEG04MC(II)_665W_12BB_银边框_横/竖装_倒斜角_高透/EPE_2384*1303*33_Q1 | F12: 组件 | G12: PC | H12: 0
A13: ==C13&D13 -> 代理商虚拟仓6B001270 | B13: JXSXNC | C13: 代理商虚拟仓 | D13: 6B001270 | E13: 销售组件_TDE-DEG04MC(II)_665W_12BB_银边框_横/竖装_倒斜角_高透/EPE_2384*1303*33_Q1 | F13: 组件 | G13: PC | H13: 0
... A3629: ==C3629&D3629 -> 天合富家-郑州仓RFBZH845 | B3629: TRP(ZZ)01 | C3629: 天合富家-郑州仓 | D3629: RFBZH845 | E3629: 备品备件_户用电站警示牌 | F3629: 其他底层物料 | G3629: PC | H3629: 1044
